<?xml version="1.0"?>
<robot xmlns:xacro="http://www.ros.org/wiki/xacro" >

    <xacro:include filename="inertial_macros.xacro" />

    <material name="white">
        <color rgba="1 1 1 1" />
    </material>

    <material name="orange">
        <color rgba="1 0.3 0.1 1"/>
    </material>

    <material name="blue">
        <color rgba="0.2 0.2 1 1"/>
    </material>

    <material name="black">
        <color rgba="0 0 0 1"/>
    </material>

    <material name="red">
        <color rgba="1 0 0 1"/>
    </material>

    <!-- BASE LINK -->

    <link name="base_link">

    </link>

    <!-- chassis joint -->
    <joint name="chassis_joint" type="fixed">
        <parent link="base_link" />
        <child link="chassis" />
        <origin xyz="-0.1 0 0" />
    </joint>

    <!-- chassis link -->
    <link name="chassis">
        <visual>
            <origin xyz="0.15 0 0.075" />
            <geometry>
                <box size="0.3 0.3 0.15" />
            </geometry>
            <material name="white" />
        </visual>
        <collision>
            <origin xyz="0.15 0 0.075" />
            <geometry>
                <box size="0.3 0.3 0.15" />
            </geometry>
        </collision>
        <xacro:inertial_box mass="0.5" x="0.3" y="0.3" z="0.15">
            <origin xyz="0.15 0 0.075" rpy="0 0 0" />
        </xacro:inertial_box>
    </link>

    <gazebo reference="chassis">
        <material>Gazebo/White</material>
    </gazebo>

    <!-- IMU joint -->
    <joint name="imu_joint" type="fixed">
        <parent link="chassis" />
        <child link="imu_link" />
        <origin xyz="0 0 0.01" />
    </joint>

    <!-- IMU link -->
    <link name="imu_link">
    <visual>
        <geometry>
        <box size="0.1 0.1 0.05"/>
        </geometry>
    </visual>

    <collision>
        <geometry>
        <box size="0.1 0.1 0.05"/>
        </geometry>
    </collision>

    <xacro:inertial_box mass="0.1" x="0.1" y="0.1" z="0.05">
        <origin xyz="0 0 0.05" rpy="0 0 0" />
    </xacro:inertial_box>
    </link>

    <!-- sensor plugin for gazebo -->
    <gazebo reference="imu_link">
        <sensor name="imu_sensor" type="imu">
        <plugin filename="libgazebo_ros_imu_sensor.so" name="imu_plugin">
            <ros>
                <namespace>/demo</namespace>
                <remapping>~/out:=imu</remapping>
            </ros>
            <initial_orientation_as_reference>false</initial_orientation_as_reference>
            </plugin>
            <always_on>true</always_on>
            <update_rate>100</update_rate>
            <visualize>true</visualize>
            <imu>
            <angular_velocity>
                <x>
                <noise type="gaussian">
                    <mean>0.0</mean>
                    <stddev>2e-4</stddev>
                    <bias_mean>0.0000075</bias_mean>
                    <bias_stddev>0.0000008</bias_stddev>
                </noise>
                </x>
                <y>
                <noise type="gaussian">
                    <mean>0.0</mean>
                    <stddev>2e-4</stddev>
                    <bias_mean>0.0000075</bias_mean>
                    <bias_stddev>0.0000008</bias_stddev>
                </noise>
                </y>
                <z>
                <noise type="gaussian">
                    <mean>0.0</mean>
                    <stddev>2e-4</stddev>
                    <bias_mean>0.0000075</bias_mean>
                    <bias_stddev>0.0000008</bias_stddev>
                </noise>
                </z>
            </angular_velocity>
            <linear_acceleration>
                <x>
                <noise type="gaussian">
                    <mean>0.0</mean>
                    <stddev>1.7e-2</stddev>
                    <bias_mean>0.1</bias_mean>
                    <bias_stddev>0.001</bias_stddev>
                </noise>
                </x>
                <y>
                <noise type="gaussian">
                    <mean>0.0</mean>
                    <stddev>1.7e-2</stddev>
                    <bias_mean>0.1</bias_mean>
                    <bias_stddev>0.001</bias_stddev>
                </noise>
                </y>
                <z>
                <noise type="gaussian">
                    <mean>0.0</mean>
                    <stddev>1.7e-2</stddev>
                    <bias_mean>0.1</bias_mean>
                    <bias_stddev>0.001</bias_stddev>
                </noise>
                </z>
            </linear_acceleration>
            </imu>
        </sensor>
    </gazebo>

    <!-- left wheel joint -->
    <joint name="left_wheel_joint" type="continuous">
        <parent link="base_link" />
        <child link="left_wheel" />
        <origin xyz="0 0.175 0" rpy="-${pi/2} 0 0" /> 
        <axis xyz="0 0 1" />
    </joint>

    <!-- left wheel link -->
    <link name="left_wheel">
        <visual>
            <geometry>
                <cylinder radius="0.05" length="0.04" />
            </geometry>
            <material name="blue" /> 
        </visual>
        <collision>
            <geometry>
                <cylinder radius="0.05" length="0.04" />
            </geometry>
        </collision>
        <xacro:inertial_cylinder mass="0.1" length="0.04" radius="0.05">
            <origin xyz="0 0 0" rpy="0 0 0" />
        </xacro:inertial_cylinder>
    </link>

    <gazebo reference="left_wheel">
        <material>Gazebo/Blue</material>
    </gazebo>

    <!-- right wheel joint -->
    <joint name="right_wheel_joint" type="continuous">
        <parent link="base_link" />
        <child link="right_wheel" />
        <origin xyz="0 -0.175 0" rpy="${pi/2} 0 0" /> 
        <axis xyz="0 0 -1" />
    </joint>

    <!-- right wheel link -->
    <link name="right_wheel">
        <visual>
            <geometry>
                <cylinder radius="0.05" length="0.04" />
            </geometry>
            <material name="blue" /> 
        </visual>
        <collision>
            <geometry>
                <cylinder radius="0.05" length="0.04" />
            </geometry>
        </collision>
        <xacro:inertial_cylinder mass="0.1" length="0.04" radius="0.05">
            <origin xyz="0 0 0" rpy="0 0 0" />
        </xacro:inertial_cylinder>
    </link>

    <gazebo reference="right_wheel">
        <material>Gazebo/Blue</material>
    </gazebo>

    <!-- caster wheel joint -->
    <joint name="caster_wheel_joint" type="fixed">
        <parent link="chassis" />
        <child link="caster_wheel" />
        <origin xyz="0.24 0 0" />
    </joint>

    <!-- caster wheel link -->
    <link name="caster_wheel">
        <visual>
            <geometry>
                <sphere radius="0.05" />
            </geometry>
            <material name="black" />
        </visual>
        <collision>
            <geometry>
                <sphere radius="0.05" />
            </geometry>
        </collision>
        <xacro:inertial_sphere mass="0.1" radius="0.05">
            <origin xyz="0 0 0" rpy="0 0 0" />
        </xacro:inertial_sphere>
    </link>

    <gazebo reference="caster_wheel">
        <material>Gazebo/Black</material>
        <mu1>0.001</mu1>
        <mu2>0.001</mu2>
    </gazebo>

</robot>